<?xml version="1.0" encoding="utf-8"?>

<robot
  name="reseq_arm_mk2" xmlns:xacro="http://www.ros.org/wiki/xacro">
  <link
    name="arm_base_link">
    <inertial>
      <origin
        xyz="0 -0.0031516 0"
        rpy="0 0 0" />
      <mass
        value="0.11481" />
      <inertia
        ixx="0.00037274"
        ixy="-3.8623E-21"
        ixz="-1.0431E-22"
        iyy="1.1022E-05"
        iyz="2.037E-21"
        izz="0.00037274" />
    </inertial>
    <visual>
      <origin
        xyz="0 0 0"
        rpy="0 0 0" />
      <geometry>
        <mesh
          filename="package://reseq_arm_mk2/meshes/arm_base_link.STL" />
      </geometry>
      <material
        name="">
        <color
          rgba="0.75294 0.75294 0.75294 1" />
      </material>
    </visual>
    <collision>
      <origin
        xyz="0 0 0"
        rpy="0 0 0" />
      <geometry>
        <mesh
          filename="package://reseq_arm_mk2/meshes/arm_base_link.STL" />
      </geometry>
    </collision>
  </link>
  <link
    name="arm_diff_pitch_link">
    <inertial>
      <origin
        xyz="-1.3878E-17 0.00059334 1.7347E-18"
        rpy="0 0 0" />
      <mass
        value="0.28931" />
      <inertia
        ixx="0.0002425"
        ixy="-1.6941E-20"
        ixz="-1.5531E-20"
        iyy="0.00023577"
        iyz="8.3058E-21"
        izz="0.00025759" />
    </inertial>
    <visual>
      <origin
        xyz="0 0 0"
        rpy="0 0 0" />
      <geometry>
        <mesh
          filename="package://reseq_arm_mk2/meshes/arm_diff_pitch_link.STL" />
      </geometry>
      <material
        name="">
        <color
          rgba="0.75294 0.75294 0.75294 1" />
      </material>
    </visual>
    <collision>
      <origin
        xyz="0 0 0"
        rpy="0 0 0" />
      <geometry>
        <mesh
          filename="package://reseq_arm_mk2/meshes/arm_diff_pitch_link.STL" />
      </geometry>
    </collision>
  </link>
  <joint
    name="mod1__base_pitch_arm_joint"
    type="revolute">
    <origin
      xyz="0 0 0"
      rpy="1.5708 -1.309 0" />
    <parent
      link="arm_base_link" />
    <child
      link="arm_diff_pitch_link" />
    <axis
      xyz="0 0 -1" />
    <limit
      lower="-1.05"
      upper="1.309"
      effort="6"
      velocity="2" />
  </joint>
  <link
    name="arm_diff_roll_link">
    <inertial>
      <origin
        xyz="1.1115E-08 7.62E-08 -0.14664"
        rpy="0 0 0" />
      <mass
        value="0.11865" />
      <inertia
        ixx="0.00051345"
        ixy="-2.7475E-10"
        ixz="-9.7641E-11"
        iyy="0.00051383"
        iyz="2.2625E-10"
        izz="1.0228E-05" />
    </inertial>
    <visual>
      <origin
        xyz="0 0 0"
        rpy="0 0 0" />
      <geometry>
        <mesh
          filename="package://reseq_arm_mk2/meshes/arm_diff_roll_link.STL" />
      </geometry>
      <material
        name="">
        <color
          rgba="0.75294 0.75294 0.75294 1" />
      </material>
    </visual>
    <collision>
      <origin
        xyz="0 0 0"
        rpy="0 0 0" />
      <geometry>
        <mesh
          filename="package://reseq_arm_mk2/meshes/arm_diff_roll_link.STL" />
      </geometry>
    </collision>
  </link>
  <joint
    name="mod1__base_roll_arm_joint"
    type="revolute">
    <origin
      xyz="0 0 0"
      rpy="1.5708 1.5708 0" />
    <parent
      link="arm_diff_pitch_link" />
    <child
      link="arm_diff_roll_link" />
    <axis
      xyz="0 0 1" />
    <limit
      lower="-3.14"
      upper="3.14"
      effort="6"
      velocity="2" />
  </joint>
  <link
    name="arm_pitch_forearm_link">
    <inertial>
      <origin
        xyz="0.060867 0.046121 -5.2042E-18"
        rpy="0 0 0" />
      <mass
        value="0.10409" />
      <inertia
        ixx="4.6765E-05"
        ixy="-9.086E-05"
        ixz="1.3681E-20"
        iyy="0.00027451"
        iyz="3.2975E-21"
        izz="0.00031255" />
    </inertial>
    <visual>
      <origin
        xyz="0 0 0"
        rpy="0 0 0" />
      <geometry>
        <mesh
          filename="package://reseq_arm_mk2/meshes/arm_pitch_forearm_link.STL" />
      </geometry>
      <material
        name="">
        <color
          rgba="0.75294 0.75294 0.75294 1" />
      </material>
    </visual>
    <collision>
      <origin
        xyz="0 0 0"
        rpy="0 0 0" />
      <geometry>
        <mesh
          filename="package://reseq_arm_mk2/meshes/arm_pitch_forearm_link.STL" />
      </geometry>
    </collision>
  </link>
  <joint
    name="mod1__elbow_pitch_arm_joint"
    type="revolute">
    <origin
      xyz="0 0 -0.28857"
      rpy="3.1416 -1.5708 3.1416" />
    <parent
      link="arm_diff_roll_link" />
    <child
      link="arm_pitch_forearm_link" />
    <axis
      xyz="0 0 1" />
    <limit
      lower="-1.05"
      upper="2.88"
      effort="6"
      velocity="2" />
  </joint>
  <link
    name="arm_roll_forearm_link">
    <inertial>
      <origin
        xyz="2.0817E-17 -0.0018789 0.03054"
        rpy="0 0 0" />
      <mass
        value="0.096867" />
      <inertia
        ixx="5.2065E-05"
        ixy="1.6912E-22"
        ixz="-6.5731E-21"
        iyy="4.9885E-05"
        iyz="2.3291E-07"
        izz="2.3052E-05" />
    </inertial>
    <visual>
      <origin
        xyz="0 0 0"
        rpy="0 0 0" />
      <geometry>
        <mesh
          filename="package://reseq_arm_mk2/meshes/arm_roll_forearm_link.STL" />
      </geometry>
      <material
        name="">
        <color
          rgba="0.75294 0.75294 0.75294 1" />
      </material>
    </visual>
    <collision>
      <origin
        xyz="0 0 0"
        rpy="0 0 0" />
      <geometry>
        <mesh
          filename="package://reseq_arm_mk2/meshes/arm_roll_forearm_link.STL" />
      </geometry>
    </collision>
  </link>
  <joint
    name="mod1__forearm_roll_arm_joint"
    type="revolute">
    <origin
      xyz="0.15351 0.074002 0"
      rpy="0.2618 -1.5708 3.1416" />
    <parent
      link="arm_pitch_forearm_link" />
    <child
      link="arm_roll_forearm_link" />
    <axis
      xyz="0 0 1" />
    <limit
      lower="-3.14"
      upper="3.14"
      effort="3"
      velocity="1" />
  </joint>
  <link
    name="arm_pitch_wrist_link">
    <inertial>
      <origin
        xyz="0.045311 1.3878E-17 -3.296E-17"
        rpy="0 0 0" />
      <mass
        value="0.056876" />
      <inertia
        ixx="1.5222E-05"
        ixy="2.5626E-21"
        ixz="3.1474E-21"
        iyy="2.2881E-05"
        iyz="-1.4326E-21"
        izz="1.6114E-05" />
    </inertial>
    <visual>
      <origin
        xyz="0 0 0"
        rpy="0 0 0" />
      <geometry>
        <mesh
          filename="package://reseq_arm_mk2/meshes/arm_pitch_wrist_link.STL" />
      </geometry>
      <material
        name="">
        <color
          rgba="0.75294 0.75294 0.75294 1" />
      </material>
    </visual>
    <collision>
      <origin
        xyz="0 0 0"
        rpy="0 0 0" />
      <geometry>
        <mesh
          filename="package://reseq_arm_mk2/meshes/arm_pitch_wrist_link.STL" />
      </geometry>
    </collision>
  </link>
  <joint
    name="mod1__wrist_pitch_arm_joint"
    type="revolute">
    <origin
      xyz="0 0 0.05447"
      rpy="3.1416 -1.5708 3.1416" />
    <parent
      link="arm_roll_forearm_link" />
    <child
      link="arm_pitch_wrist_link" />
    <axis
      xyz="0 0 -1" />
    <limit
      lower="-0.46"
      upper="1.57"
      effort="3"
      velocity="1" />
  </joint>
  <link
    name="arm_roll_wrist_link">
    <inertial>
      <origin
        xyz="2.6021E-17 0.0094155 0.12425"
        rpy="0 0 0" />
      <mass
        value="0.55801" />
      <inertia
        ixx="0.00046764"
        ixy="1.372E-19"
        ixz="1.5587E-19"
        iyy="0.000956"
        iyz="7.6437E-06"
        izz="0.00082011" />
    </inertial>
    <visual>
      <origin
        xyz="0 0 0"
        rpy="0 0 0" />
      <geometry>
        <mesh
          filename="package://reseq_arm_mk2/meshes/arm_roll_wrist_link.STL" />
      </geometry>
      <material
        name="">
        <color
          rgba="0.75294 0.75294 0.75294 1" />
      </material>
    </visual>
    <collision>
      <origin
        xyz="0 0 0"
        rpy="0 0 0" />
      <geometry>
        <mesh
          filename="package://reseq_arm_mk2/meshes/arm_roll_wrist_link.STL" />
      </geometry>
    </collision>
  </link>
  <joint
    name="mod1__wrist_roll_arm_joint"
    type="revolute">
    <origin
      xyz="0 0 0"
      rpy="0 1.5708 0" />
    <parent
      link="arm_pitch_wrist_link" />
    <child
      link="arm_roll_wrist_link" />
    <axis
      xyz="0 0 -1" />
    <limit
      lower="-3.14"
      upper="3.14"
      effort="3"
      velocity="1" />
  </joint>
</robot>